.	System.AggregateException: One or more errors occurred. (Exception with async)
 ---> System.Exception: Exception with async
   at CatchPoint.Core.Tests.ExceptionParserTests.AsyncThrowingFun() in C:\Users\Yaniv\source\repos\CatchPoint\CatchPoint.Core.Tests\ExceptionParserTests.cs:line 45
   --- End of inner exception stack trace ---
   at System.Threading.Tasks.Task.Wait(Int32 millisecondsTimeout, CancellationToken cancellationToken)
   at System.Threading.Tasks.Task.Wait()
   at CatchPoint.Core.Tests.ExceptionParserTests.CreateExceptionWithAsync() in C:\Users\Yaniv\source\repos\CatchPoint\CatchPoint.Core.Tests\ExceptionParserTests.cs:line 33





System.Exception: my message
at CatchPoint.Core.Tests.ExceptionParserTests.ThrowException() in C:\Users\Yaniv\source\repos\CatchPoint\CatchPoint.Core.Tests\ExceptionParserTests.cs:line 57
at CatchPoint.Core.Tests.ExceptionParserTests.CreateException() in C:\Users\Yaniv\source\repos\CatchPoint\CatchPoint.Core.Tests\ExceptionParserTests.cs:line 45


System.Exception: outer ex
 ---> System.Exception: This is the inner
   at CatchPoint.Core.Tests.ExceptionParserTests.CreateExceptionWithInner() in C:\Users\Yaniv\source\repos\CatchPoint\CatchPoint.Core.Tests\ExceptionParserTests.cs:line 41
   --- End of inner exception stack trace ---
   at CatchPoint.Core.Tests.ExceptionParserTests.CreateExceptionWithInner() in C:\Users\Yaniv\source\repos\CatchPoint\CatchPoint.Core.Tests\ExceptionParserTests.cs:line 45